Workbook

Sheet Bảng tổng hợp hàng trên hóa đơn
B1: ĐỐI CHIẾU HÀNG HÓA MOONPO - VANDA T9.25
A3: STT | B3: Tên hóa đơn | C3: ĐVT | D3: Số lượng | E3: Đơn giá | F3: Thành tiền
A4: 1 | B4: Cờ lê lực, dùng để tháo lắp ốc vít, bulong | C4: Cái | D4: =SUMIF('Bản đối chiếu chi tiết - Final'!J4:L63,'Bảng tổng hợp hàng trên hóa đơn'!B4,'Bản đối chiếu chi tiết - Final'!L4:L63) -> 1 | E4: 1400000 | F4: =D4*E4 -> 1400000
A5: 2 | B5: Mũi hàn 200-3C | C5: Cái | D5: =SUMIF('Bản đối chiếu chi tiết - Final'!J5:L63,'Bảng tổng hợp hàng trên hóa đơn'!B5,'Bản đối chiếu chi tiết - Final'!L5:L63) -> 362 | E5: 14000 | F5: =D5*E5 -> 5068000
A6: 3 | B6: Máy đọc mã vạch sử dụng tia hồng ngoại, model: T-4503E | C6: Cái | D6: =SUMIF('Bản đối chiếu chi tiết - Final'!J6:L64,'Bảng tổng hợp hàng trên hóa đơn'!B6,'Bản đối chiếu chi tiết - Final'!L6:L64) -> 1 | E6: 6650000 | F6: =D6*E6 -> 6650000
A7: 4 | B7: Mũi hàn 200-2C | C7: Cái | D7: =SUMIF('Bản đối chiếu chi tiết - Final'!J7:L65,'Bảng tổng hợp hàng trên hóa đơn'!B7,'Bản đối chiếu chi tiết - Final'!L7:L65) -> 200 | E7: 15000 | F7: =D7*E7 -> 3000000
A8: 5 | B8: Mũi hàn 200-4C | C8: Cái | D8: =SUMIF('Bản đối chiếu chi tiết - Final'!J8:L66,'Bảng tổng hợp hàng trên hóa đơn'!B8,'Bản đối chiếu chi tiết - Final'!L8:L66) -> 100 | E8: 16000 | F8: =D8*E8 -> 1600000
A9: 6 | B9: Mũi hàn 900M-T-2C | C9: Cái | D9: =SUMIF('Bản đối chiếu chi tiết - Final'!J9:L67,'Bảng tổng hợp hàng trên hóa đơn'!B9,'Bản đối chiếu chi tiết - Final'!L9:L67) -> 100 | E9: 16000 | F9: =D9*E9 -> 1600000
A10: 7 | B10: Mũi hàn 900M-T-3C | C10: Cái | D10: =SUMIF('Bản đối chiếu chi tiết - Final'!J10:L68,'Bảng tổng hợp hàng trên hóa đơn'!B10,'Bản đối chiếu chi tiết - Final'!L10:L68) -> 200 | E10: 17000 | F10: =D10*E10 -> 3400000
A11: 8 | B11: Mũi hàn 900M-T-4C | C11: Cái | D11: =SUMIF('Bản đối chiếu chi tiết - Final'!J11:L69,'Bảng tổng hợp hàng trên hóa đơn'!B11,'Bản đối chiếu chi tiết - Final'!L11:L69) -> 100 | E11: 18000 | F11: =D11*E11 -> 1800000
A12: 9 | B12: Tay máy hàn model 203H | C12: Cái | D12: =SUMIF('Bản đối chiếu chi tiết - Final'!J12:L70,'Bảng tổng hợp hàng trên hóa đơn'!B12,'Bản đối chiếu chi tiết - Final'!L12:L70) -> 36 | E12: 220000 | F12: =D12*E12 -> 7920000
A13: 10 | B13: Vòng bi NTN 6200LLU/2AS | C13: Cái | D13: =SUMIF('Bản đối chiếu chi tiết - Final'!J13:L71,'Bảng tổng hợp hàng trên hóa đơn'!B13,'Bản đối chiếu chi tiết - Final'!L13:L71) -> 5 | E13: 108000 | F13: =D13*E13 -> 540000
A14: 11 | B14: Vòng bi NTN 6201LLU/2AS | C14: Cái | D14: =SUMIF('Bản đối chiếu chi tiết - Final'!J14:L72,'Bảng tổng hợp hàng trên hóa đơn'!B14,'Bản đối chiếu chi tiết - Final'!L14:L72) -> 5 | E14: 115000 | F14: =D14*E14 -> 575000
A15: 12 | B15: Thiết bị đo nhiệt độ và độ ẩm môi trường, mã HTC-1 | C15: Cái | D15: =SUMIF('Bản đối chiếu chi tiết - Final'!J15:L73,'Bảng tổng hợp hàng trên hóa đơn'!B15,'Bản đối chiếu chi tiết - Final'!L15:L73) -> 2 | E15: 965000 | F15: =D15*E15 -> 1930000
A16: 13 | B16: Rơ le SRD-12VDC-SL-C Relay 12V 10A/250V 5 chân CH SONGLE | C16: Chiếc | D16: =SUMIF('Bản đối chiếu chi tiết - Final'!J16:L74,'Bảng tổng hợp hàng trên hóa đơn'!B16,'Bản đối chiếu chi tiết - Final'!L16:L74) -> 20 | E16: 12000 | F16: =D16*E16 -> 240000
... A36: 33 | B36: Giắc cắm kết nối âm thanh XLR Canon Female Soundline NC3FXX, hiệu Soundline | C36: Cái | D36: =SUMIF('Bản đối chiếu chi tiết - Final'!J36:L94,'Bảng tổng hợp hàng trên hóa đơn'!B36,'Bản đối chiếu chi tiết - Final'!L36:L94) -> 30 | E36: 50000 | F36: =D36*E36 -> 1500000
B37: Tổng tiền | F37: =SUM(F4:F36) -> 56400000

Sheet Bản đối chiếu chi tiết - Check
A1: ĐỐI CHIẾU HÀNG HÓA MOONPO - VANDA T9.25 | J1: PR
A3: STT | B3: Description of goods & services | C3: Specific Description | D3: Unit | E3: Quantity | F3: Unit Price (vnd) | G3: Total Amount (EXT VAT) | H3: PO | K3: Tên hóa đơn | L3: ĐVT | M3: Số lượng | N3: Đơn giá | O3: Thành tiền
A4: 1 | B4: Cờ Lê lực | C4: 0,5-5N dài 215mm | D4: PCS | E4: 1 | F4: 1400000 | G4: =E4*F4 -> 1400000 | H4: PIE250413 | J4: 250399-1115 | K4: Cờ lê lực, dùng để tháo lắp ốc vít, bulong | L4: Cái | M4: 1 | N4: 1400000 | O4: =M4*N4 -> 1400000
A5: 2 | B5: Đầu cờ lê | C5: 11mm | D5: PCS | E5: 1 | F5: 195000 | G5: =E5*F5 -> 195000 | H5: PIE250413 | J5: 250413-1115 | K5: Mũi hàn 200-3C | L5: Cái | M5: 15 | N5: 14000 | O5: =M5*N5 -> 210000
A6: 3 | B6: Đầu cờ lê | C6: 12mm | D6: PCS | E6: 1 | F6: 195000 | G6: =E6*F6 -> 195000 | H6: PIE250413 | K6: Mũi hàn 200-3C | L6: Cái | M6: 13 | N6: 14000 | O6: =M6*N6 -> 182000
G7: =SUBTOTAL(9,G4:G6) -> 1790000 | O7: =SUBTOTAL(9,O4:O6) -> 1792000
A8: 1 | B8: Máy quét mã vạch TSC 300 Dpi T4503E | D8: Cái | E8: 1 | F8: 6650000 | G8: =E8*F8 -> 6650000 | H8: PIE250458 | J8: 250458-1115 | K8: Máy đọc mã vạch sử dụng tia hồng ngoại, model: T-4503E | L8: Cái | M8: 1 | N8: 6650000 | O8: =M8*N8 -> 6650000
G9: =SUBTOTAL(9,G8) -> 6650000 | O9: =SUBTOTAL(9,O8) -> 6650000
A10: 1 | B10: Dây AV (L-R) 2 đầu (0.8m) | D10: pcs | E10: 10 | F10: 48000 | G10: =E10*F10 -> 480000 | H10: PIE250469 | J10: 250469-1115 | K10: Mũi hàn 200-3C | L10: Cái | M10: 26 | N10: 14000 | O10: =M10*N10 -> 364000
A11: 2 | B11: Jack chuyển đổi 6 ly sang AV hoa sen cong vuông góc | D11: pcs | E11: 10 | F11: 75000 | G11: =E11*F11 -> 750000 | H11: PIE250469 | K11: Mũi hàn 200-3C | L11: Cái | M11: 26 | N11: 14000 | O11: =M11*N11 -> 364000
A12: 3 | B12: Dây 2 đầu 2ly cong chữ L góc vuông (1m) | D12: pcs | E12: 10 | F12: 50000 | G12: =E12*F12 -> 500000 | H12: PIE250469 | K12: Mũi hàn 200-2C | L12: Cái | M12: 67 | N12: 15000 | O12: =M12*N12 -> 1005000
G13: =SUBTOTAL(9,G10:G12) -> 1730000 | O13: =SUBTOTAL(9,O10:O12) -> 1733000
A14: 1 | B14: Flux | D14: box | E14: 2 | F14: 250000 | G14: =E14*F14 -> 500000 | H14: PIE250481 | J14: 250481-1115 | K14: Mũi hàn 200-2C | L14: Cái | M14: 33 | N14: 15000 | O14: =M14*N14 -> 495000
G15: =SUBTOTAL(9,G14) -> 500000 | O15: =SUBTOTAL(9,O14) -> 495000
A16: 1 | B16: Mũi hàn 200-2C | D16: pcs | E16: 100 | F16: 15000 | G16: =E16*F16 -> 1500000 | H16: PIE250514 | J16: 250514-1115 | K16: Mũi hàn 200-2C | L16: cái | M16: 100 | N16: 15000 | O16: =M16*N16 -> 1500000
A17: 2 | B17: Mũi hàn 200-3C | D17: pcs | E17: 200 | F17: 14000 | G17: =E17*F17 -> 2800000 | H17: PIE250514 | K17: Mũi hàn 200-3C | L17: Cái | M17: 200 | N17: 14000 | O17: =M17*N17 -> 2800000
A18: 3 | B18: Mũi hàn 200-4C | D18: pcs | E18: 100 | F18: 16000 | G18: =E18*F18 -> 1600000 | H18: PIE250514 | K18: Mũi hàn 200-4C | L18: Cái | M18: 100 | N18: 16000 | O18: =M18*N18 -> 1600000
A19: 4 | B19: Mũi hàn 900M-T-2C | D19: pcs | E19: 100 | F19: 16000 | G19: =E19*F19 -> 1600000 | H19: PIE250514 | K19: Mũi hàn 900M-T-2C | L19: Cái | M19: 100 | N19: 16000 | O19: =M19*N19 -> 1600000
A20: 5 | B20: Mũi hàn 900M-T-3C | D20: pcs | E20: 200 | F20: 17000 | G20: =E20*F20 -> 3400000 | H20: PIE250514 | K20: Mũi hàn 900M-T-3C | L20: Cái | M20: 200 | N20: 17000 | O20: =M20*N20 -> 3400000
A21: 6 | B21: Mũi hàn 900M-T-4C | D21: pcs | E21: 100 | F21: 18000 | G21: =E21*F21 -> 1800000 | H21: PIE250514 | K21: Mũi hàn 900M-T-4C | L21: Cái | M21: 100 | N21: 18000 | O21: =M21*N21 -> 1800000
G22: =SUBTOTAL(9,G16:G21) -> 12700000 | O22: =SUBTOTAL(9,O16:O21) -> 12700000
A23: 1 | B23: Mỡ bảo dưỡng AFJ | D23: PCS | E23: 4 | F23: 1980000 | G23: =E23*F23 -> 7920000 | H23: PIE250614 | J23: 250614-1115 | K23: Tay máy hàn model 203H | L23: Cái | M23: 36 | N23: 220000 | O23: =M23*N23 -> 7920000
A24: 2 | B24: Vòng bi 6200LLU/2A | D24: PCS | E24: 5 | F24: 108000 | G24: =E24*F24 -> 540000 | H24: PIE250614 | K24: Vòng bi NTN 6200LLU/2AS | L24: Cái | M24: 5 | N24: 108000 | O24: =M24*N24 -> 540000
A25: 3 | B25: Vòng bi 6201LLU/2AS | D25: PCS | E25: 5 | F25: 115000 | G25: =E25*F25 -> 575000 | H25: PIE250614 | K25: Vòng bi NTN 6201LLU/2AS | L25: Cái | M25: 5 | N25: 115000 | O25: =M25*N25 -> 575000
A26: 4 | B26: Nhiệt kế đo nhiệt độ, độ ẩm HTC-1, kèm hiệu chuẩn | D26: PCS | E26: 2 | F26: 965000 | G26: =E26*F26 -> 1930000 | H26: PIE250614 | K26: Thiết bị đo nhiệt độ và độ ẩm môi trường, mã HTC-1 | L26: Cái | M26: 2 | N26: 965000 | O26: =M26*N26 -> 1930000
G27: =SUBTOTAL(9,G23:G26) -> 10965000 | O27: =SUBTOTAL(9,O23:O26) -> 10965000
A28: 1 | B28: Relay SRD-12VDC-SL-C | D28: PCS | E28: 20 | F28: 12000 | G28: =E28*F28 -> 240000 | H28: PIE250613 | J28: 250613-1115 | K28: Rơ le SRD-12VDC-SL-C Relay 12V 10A/250V 5 chân CH SONGLE | L28: Chiếc | M28: 20 | N28: 12000 | O28: =M28*N28 -> 240000
A29: 2 | B29: Lưới nhựa mủ màu đen làm chuồng trại chăn nuôi chất lượng bán theo M | D29: M | E29: 5 | F29: 75000 | G29: =E29*F29 -> 375000 | H29: PIE250613 | K29: Mũi hàn 200-3C | L29: Cái | M29: 50 | N29: 14000 | O29: =M29*N29 -> 700000
A30: 3 | B30: Kẹp đẩy ngang GH 30SEM | D30: PCS | E30: 5 | F30: 165000 | G30: =E30*F30 -> 825000 | H30: PIE250613 | K30: Mũi Hàn To 200K | L30: Cái | M30: 50 | N30: 19000 | O30: =M30*N30 -> 950000
A31: 4 | B31: Ốc M2x6mm | D31: PCS | E31: 200 | F31: 900 | G31: =E31*F31 -> 180000 | H31: PIE250613 | K31: Vít bulông đầu tròn inox M2 x 6 | L31: Cái | M31: 200 | N31: 900 | O31: =M31*N31 -> 180000
A32: 5 | B32: GX16-2P đực | D32: PCS | E32: 100 | F32: 6200 | G32: =E32*F32 -> 620000 | H32: PIE250613 | K32: Mũi hàn nhỏ 200-SK | L32: Cái | M32: 60 | N32: 19000 | O32: =M32*N32 -> 1140000
A33: 6 | B33: Phụ kiện máy đo lực súng HP-50 loại A | D33: PCS | E33: 2 | F33: 680000 | G33: =E33*F33 -> 1360000 | H33: PIE250613 | K33: Đầu xoắn máy đo lực model: HP-50 bằng thép | L33: Cái | M33: 1 | N33: 680000 | O33: =M33*N33 -> 680000
A34: 7 | B34: hộp nhựa ABS kích thước 115x90x55mm ( chống nước IP65) | D34: Hộp | E34: 10 | F34: 65000 | G34: =E34*F34 -> 650000 | H34: PIE250613 | K34: Thùng đựng linh kiện điện tử ESD bằng nhựa, kt: 310*270*140MM | L34: Cái | M34: 10 | N34: 150000 | O34: =M34*N34 -> 1500000
A35: 8 | B35: Đầu jack bắp chuối 910MR 4mm đực đỏ - đen | D35: Đôi | E35: 50 | F35: 10000 | G35: =E35*F35 -> 500000 | H35: PIE250613 | K35: Đầu jack M5 đầu nối điện cho dây nguồn DC, điện áp 24V, 5A | L35: Cái | M35: 10 | N35: 20000 | O35: =M35*N35 -> 200000
A36: 9 | B36: Ống dẫn thiếc máy hàn tự động Quick 376 | D36: pcs | E36: 5 | F36: 380000 | G36: =E36*F36 -> 1900000 | H36: PIE250613 | K36: DÂY MÁY HÀN QUICK 203H | L36: Cái | M36: 5 | N36: 290000 | O36: =M36*N36 -> 1450000
A37: 10 | B37: Đầu kết nối BNC cái | D37: pcs | E37: 5 | F37: 10000 | G37: =E37*F37 -> 50000 | H37: PIE250613 | K37: Đầu BNC T | L37: Cái | M37: 20 | N37: 25000 | O37: =M37*N37 -> 500000
A38: 11 | B38: Ống gen thủy tinh cách điện, chịu nhiệt cao, chống cháy - phi 3 | D38: m | E38: 20 | F38: 12000 | G38: =E38*F38 -> 240000 | H38: PIE250613 | K38: Mũi hàn 200-3C | L38: Cái | M38: 50 | N38: 14000 | O38: =M38*N38 -> 700000
A39: 12 | B39: Dây cáp nguồn DC đầu đực, cỡ jack 5525, dây 22 AWG, chiều dài 15cm | D39: pcs | E39: 20 | F39: 6000 | G39: =E39*F39 -> 120000 | H39: PIE250613 | K39: Mũi Hàn To 200K | L39: Cái | M39: 45 | N39: 19000 | O39: =M39*N39 -> 855000
A40: 13 | B40: Bi 3mm (1kg) | D40: kg | E40: 1 | F40: 195000 | G40: =E40*F40 -> 195000 | H40: PIE250613 | K40: Van bi nhựa, đường kính trong 15mm, dùng để điều chỉnh đóng mở nước | L40: Cái | M40: 10 | N40: 85000 | O40: =M40*N40 -> 850000
... A48: 21 | B48: Dây đo đồng hồ vạn năng | D48: đôi | E48: 5 | F48: 68000 | G48: =E48*F48 -> 340000 | H48: PIE250613 | K48: Dây nguồn 2 chân dài 60cm | L48: Cái | M48: 5 | N48: 90000 | O48: =M48*N48 -> 450000
...

Sheet Bản đối chiếu chi tiết - Final
A1: ĐỐI CHIẾU HÀNG HÓA MOONPO - VANDA T9.25
A3: STT | B3: Description of goods & services | C3: Specific Description | D3: Unit | E3: Quantity | F3: Unit Price (vnd) | G3: Total Amount (EXT VAT) | H3: PO | J3: Tên hóa đơn | K3: ĐVT | L3: Số lượng | M3: Đơn giá | N3: Thành tiền
A4: 1 | B4: Cờ Lê lực | C4: 0,5-5N dài 215mm | D4: PCS | E4: 1 | F4: 1400000 | G4: =E4*F4 -> 1400000 | H4: PIE250413 | J4: Cờ lê lực, dùng để tháo lắp ốc vít, bulong | K4: Cái | L4: 1 | M4: 1400000 | N4: =L4*M4 -> 1400000
A5: 2 | B5: Đầu cờ lê | C5: 11mm | D5: PCS | E5: 1 | F5: 195000 | G5: =E5*F5 -> 195000 | H5: PIE250413 | J5: Mũi hàn 200-3C | K5: Cái | L5: 15 | M5: 14000 | N5: =L5*M5 -> 210000
A6: 3 | B6: Đầu cờ lê | C6: 12mm | D6: PCS | E6: 1 | F6: 195000 | G6: =E6*F6 -> 195000 | H6: PIE250413 | J6: Mũi hàn 200-3C | K6: Cái | L6: 13 | M6: 14000 | N6: =L6*M6 -> 182000
G7: =SUBTOTAL(9,G4:G6) -> 1790000 | N7: =SUBTOTAL(9,N4:N6) -> 1792000
A8: 1 | B8: Máy quét mã vạch TSC 300 Dpi T4503E | D8: Cái | E8: 1 | F8: 6650000 | G8: =E8*F8 -> 6650000 | H8: PIE250458 | J8: Máy đọc mã vạch sử dụng tia hồng ngoại, model: T-4503E | K8: Cái | L8: 1 | M8: 6650000 | N8: =L8*M8 -> 6650000
G9: =SUBTOTAL(9,G8) -> 6650000 | N9: =SUBTOTAL(9,N8) -> 6650000
A10: 1 | B10: Dây AV (L-R) 2 đầu (0.8m) | D10: pcs | E10: 10 | F10: 48000 | G10: =E10*F10 -> 480000 | H10: PIE250469 | J10: Mũi hàn 200-3C | K10: Cái | L10: 26 | M10: 14000 | N10: =L10*M10 -> 364000
A11: 2 | B11: Jack chuyển đổi 6 ly sang AV hoa sen cong vuông góc | D11: pcs | E11: 10 | F11: 75000 | G11: =E11*F11 -> 750000 | H11: PIE250469 | J11: Mũi hàn 200-3C | K11: Cái | L11: 26 | M11: 14000 | N11: =L11*M11 -> 364000
A12: 3 | B12: Dây 2 đầu 2ly cong chữ L góc vuông (1m) | D12: pcs | E12: 10 | F12: 50000 | G12: =E12*F12 -> 500000 | H12: PIE250469 | J12: Mũi hàn 200-2C | K12: Cái | L12: 67 | M12: 15000 | N12: =L12*M12 -> 1005000
G13: =SUBTOTAL(9,G10:G12) -> 1730000 | N13: =SUBTOTAL(9,N10:N12) -> 1733000
A14: 1 | B14: Flux | D14: box | E14: 2 | F14: 250000 | G14: =E14*F14 -> 500000 | H14: PIE250481 | J14: Mũi hàn 200-2C | K14: Cái | L14: 33 | M14: 15000 | N14: =L14*M14 -> 495000
G15: =SUBTOTAL(9,G14) -> 500000 | N15: =SUBTOTAL(9,N14) -> 495000
A16: 1 | B16: Mũi hàn 200-2C | D16: pcs | E16: 100 | F16: 15000 | G16: =E16*F16 -> 1500000 | H16: PIE250514 | J16: Mũi hàn 200-2C | K16: cái | L16: 100 | M16: 15000 | N16: =L16*M16 -> 1500000
A17: 2 | B17: Mũi hàn 200-3C | D17: pcs | E17: 200 | F17: 14000 | G17: =E17*F17 -> 2800000 | H17: PIE250514 | J17: Mũi hàn 200-3C | K17: Cái | L17: 200 | M17: 14000 | N17: =L17*M17 -> 2800000
A18: 3 | B18: Mũi hàn 200-4C | D18: pcs | E18: 100 | F18: 16000 | G18: =E18*F18 -> 1600000 | H18: PIE250514 | J18: Mũi hàn 200-4C | K18: Cái | L18: 100 | M18: 16000 | N18: =L18*M18 -> 1600000
A19: 4 | B19: Mũi hàn 900M-T-2C | D19: pcs | E19: 100 | F19: 16000 | G19: =E19*F19 -> 1600000 | H19: PIE250514 | J19: Mũi hàn 900M-T-2C | K19: Cái | L19: 100 | M19: 16000 | N19: =L19*M19 -> 1600000
A20: 5 | B20: Mũi hàn 900M-T-3C | D20: pcs | E20: 200 | F20: 17000 | G20: =E20*F20 -> 3400000 | H20: PIE250514 | J20: Mũi hàn 900M-T-3C | K20: Cái | L20: 200 | M20: 17000 | N20: =L20*M20 -> 3400000
A21: 6 | B21: Mũi hàn 900M-T-4C | D21: pcs | E21: 100 | F21: 18000 | G21: =E21*F21 -> 1800000 | H21: PIE250514 | J21: Mũi hàn 900M-T-4C | K21: Cái | L21: 100 | M21: 18000 | N21: =L21*M21 -> 1800000
G22: =SUBTOTAL(9,G16:G21) -> 12700000 | N22: =SUBTOTAL(9,N16:N21) -> 12700000
A23: 1 | B23: Mỡ bảo dưỡng AFJ | D23: PCS | E23: 4 | F23: 1980000 | G23: =E23*F23 -> 7920000 | H23: PIE250614 | J23: Tay máy hàn model 203H | K23: Cái | L23: 36 | M23: 220000 | N23: =L23*M23 -> 7920000
A24: 2 | B24: Vòng bi 6200LLU/2A | D24: PCS | E24: 5 | F24: 108000 | G24: =E24*F24 -> 540000 | H24: PIE250614 | J24: Vòng bi NTN 6200LLU/2AS | K24: Cái | L24: 5 | M24: 108000 | N24: =L24*M24 -> 540000
A25: 3 | B25: Vòng bi 6201LLU/2AS | D25: PCS | E25: 5 | F25: 115000 | G25: =E25*F25 -> 575000 | H25: PIE250614 | J25: Vòng bi NTN 6201LLU/2AS | K25: Cái | L25: 5 | M25: 115000 | N25: =L25*M25 -> 575000
A26: 4 | B26: Nhiệt kế đo nhiệt độ, độ ẩm HTC-1, kèm hiệu chuẩn | D26: PCS | E26: 2 | F26: 965000 | G26: =E26*F26 -> 1930000 | H26: PIE250614 | J26: Thiết bị đo nhiệt độ và độ ẩm môi trường, mã HTC-1 | K26: Cái | L26: 2 | M26: 965000 | N26: =L26*M26 -> 1930000
G27: =SUBTOTAL(9,G23:G26) -> 10965000 | N27: =SUBTOTAL(9,N23:N26) -> 10965000
A28: 1 | B28: Relay SRD-12VDC-SL-C | D28: PCS | E28: 20 | F28: 12000 | G28: =E28*F28 -> 240000 | H28: PIE250613 | J28: Rơ le SRD-12VDC-SL-C Relay 12V 10A/250V 5 chân CH SONGLE | K28: Chiếc | L28: 20 | M28: 12000 | N28: =L28*M28 -> 240000
A29: 2 | B29: Lưới nhựa mủ màu đen làm chuồng trại chăn nuôi chất lượng bán theo M | D29: M | E29: 5 | F29: 75000 | G29: =E29*F29 -> 375000 | H29: PIE250613 | J29: Mũi hàn 200-3C | K29: Cái | L29: 52 | M29: 14000 | N29: =L29*M29 -> 728000
A30: 3 | B30: Kẹp đẩy ngang GH 30SEM | D30: PCS | E30: 5 | F30: 165000 | G30: =E30*F30 -> 825000 | H30: PIE250613 | J30: Mũi Hàn To 200K | K30: Cái | L30: 40 | M30: 19000 | N30: =L30*M30 -> 760000
A31: 4 | B31: Ốc M2x6mm | D31: PCS | E31: 200 | F31: 900 | G31: =E31*F31 -> 180000 | H31: PIE250613 | J31: Vít bulông đầu tròn inox M2 x 6 | K31: Cái | L31: 200 | M31: 900 | N31: =L31*M31 -> 180000
A32: 5 | B32: GX16-2P đực | D32: PCS | E32: 100 | F32: 6200 | G32: =E32*F32 -> 620000 | H32: PIE250613 | J32: Mũi hàn nhỏ 200-SK | K32: Cái | L32: 10 | M32: 19000 | N32: =L32*M32 -> 190000
A33: 6 | B33: Phụ kiện máy đo lực súng HP-50 loại A | D33: PCS | E33: 2 | F33: 680000 | G33: =E33*F33 -> 1360000 | H33: PIE250613 | J33: Đầu xoắn máy đo lực model: HP-50 bằng thép | K33: Cái | L33: 1 | M33: 680000 | N33: =L33*M33 -> 680000
A34: 7 | B34: hộp nhựa ABS kích thước 115x90x55mm ( chống nước IP65) | D34: Hộp | E34: 10 | F34: 65000 | G34: =E34*F34 -> 650000 | H34: PIE250613 | J34: Thùng đựng linh kiện điện tử ESD bằng nhựa, kt: 310*270*140MM | K34: Cái | L34: 10 | M34: 150000 | N34: =L34*M34 -> 1500000
A35: 8 | B35: Đầu jack bắp chuối 910MR 4mm đực đỏ - đen | D35: Đôi | E35: 50 | F35: 10000 | G35: =E35*F35 -> 500000 | H35: PIE250613 | J35: Đầu jack M5 đầu nối điện cho dây nguồn DC, điện áp 24V, 5A | K35: Cái | L35: 10 | M35: 20000 | N35: =L35*M35 -> 200000
A36: 9 | B36: Ống dẫn thiếc máy hàn tự động Quick 376 | D36: pcs | E36: 5 | F36: 380000 | G36: =E36*F36 -> 1900000 | H36: PIE250613 | J36: DÂY MÁY HÀN QUICK 203H | K36: Cái | L36: 5 | M36: 290000 | N36: =L36*M36 -> 1450000
A37: 10 | B37: Đầu kết nối BNC cái | D37: pcs | E37: 5 | F37: 10000 | G37: =E37*F37 -> 50000 | H37: PIE250613 | J37: Đầu BNC T | K37: Cái | L37: 20 | M37: 25000 | N37: =L37*M37 -> 500000
A38: 11 | B38: Ống gen thủy tinh cách điện, chịu nhiệt cao, chống cháy - phi 3 | D38: m | E38: 20 | F38: 12000 | G38: =E38*F38 -> 240000 | H38: PIE250613 | J38: Mũi hàn 200-3C | K38: Cái | L38: 30 | M38: 14000 | N38: =L38*M38 -> 420000
A39: 12 | B39: Dây cáp nguồn DC đầu đực, cỡ jack 5525, dây 22 AWG, chiều dài 15cm | D39: pcs | E39: 20 | F39: 6000 | G39: =E39*F39 -> 120000 | H39: PIE250613 | J39: Mũi Hàn To 200K | K39: Cái | L39: 45 | M39: 19000 | N39: =L39*M39 -> 855000
... A48: 21 | B48: Dây đo đồng hồ vạn năng | D48: đôi | E48: 5 | F48: 68000 | G48: =E48*F48 -> 340000 | H48: PIE250613 | J48: Dây nguồn 2 chân dài 60cm | K48: Cái | L48: 5 | M48: 90000 | N48: =L48*M48 -> 450000
G49: =SUBTOTAL(9,G28:G48) -> 12385000 | N49: =SUBTOTAL(9,N28:N48) -> 12377000
...

Sheet Chốt - Gộp PO
B1: HÀNG HÓA MOONPO - VANDA T9.25 ( GỘP PO)
A3: STT | B3: Tên hóa đơn | C3: ĐVT | D3: Số lượng | E3: Đơn giá | F3: Thành tiền | G3: PO | H3: Ngày PO
A4: 1 | B4: Cờ lê lực, dùng để tháo lắp ốc vít, bulong | C4: Cái | D4: =SUMIF('[1]Bản đối chiếu chi tiết'!J4:L63,'Chốt - Gộp PO'!B4,'[1]Bản đối chiếu chi tiết'!L4:L63) -> 1 | E4: 1400000 | F4: =D4*E4 -> 1400000 | G4: PIE250613 | H4: 45884
A5: 2 | B5: Mũi hàn 200-3C | C5: Cái | D5: =SUMIF('[1]Bản đối chiếu chi tiết'!J5:L63,'Chốt - Gộp PO'!B5,'[1]Bản đối chiếu chi tiết'!L5:L63) -> 362 | E5: 14000 | F5: =D5*E5 -> 5068000 | G5: PIE250613 | H5: 45884
A6: 3 | B6: Máy đọc mã vạch sử dụng tia hồng ngoại, model: T-4503E | C6: Cái | D6: =SUMIF('[1]Bản đối chiếu chi tiết'!J6:L64,'Chốt - Gộp PO'!B6,'[1]Bản đối chiếu chi tiết'!L6:L64) -> 1 | E6: 6650000 | F6: =D6*E6 -> 6650000 | G6: PIE250613 | H6: 45884
A7: 4 | B7: Mũi hàn 200-2C | C7: Cái | D7: =SUMIF('[1]Bản đối chiếu chi tiết'!J7:L65,'Chốt - Gộp PO'!B7,'[1]Bản đối chiếu chi tiết'!L7:L65) -> 200 | E7: 15000 | F7: =D7*E7 -> 3000000 | G7: PIE250613 | H7: 45884
A8: 5 | B8: Mũi hàn 200-4C | C8: Cái | D8: =SUMIF('[1]Bản đối chiếu chi tiết'!J8:L66,'Chốt - Gộp PO'!B8,'[1]Bản đối chiếu chi tiết'!L8:L66) -> 100 | E8: 16000 | F8: =D8*E8 -> 1600000 | G8: PIE250613 | H8: 45884
A9: 6 | B9: Mũi hàn 900M-T-2C | C9: Cái | D9: =SUMIF('[1]Bản đối chiếu chi tiết'!J9:L67,'Chốt - Gộp PO'!B9,'[1]Bản đối chiếu chi tiết'!L9:L67) -> 100 | E9: 16000 | F9: =D9*E9 -> 1600000 | G9: PIE250613 | H9: 45884
A10: 7 | B10: Mũi hàn 900M-T-3C | C10: Cái | D10: =SUMIF('[1]Bản đối chiếu chi tiết'!J10:L68,'Chốt - Gộp PO'!B10,'[1]Bản đối chiếu chi tiết'!L10:L68) -> 200 | E10: 17000 | F10: =D10*E10 -> 3400000 | G10: PIE250613 | H10: 45884
F11: =SUBTOTAL(9,F4:F10) -> 22718000
A12: 8 | B12: Mũi hàn 900M-T-4C | C12: Cái | D12: =SUMIF('[1]Bản đối chiếu chi tiết'!J11:L69,'Chốt - Gộp PO'!B12,'[1]Bản đối chiếu chi tiết'!L11:L69) -> 100 | E12: 18000 | F12: =D12*E12 -> 1800000 | G12: PIE250770 | H12: 45905
A13: 9 | B13: Tay máy hàn model 203H | C13: Cái | D13: =SUMIF('[1]Bản đối chiếu chi tiết'!J12:L70,'Chốt - Gộp PO'!B13,'[1]Bản đối chiếu chi tiết'!L12:L70) -> 36 | E13: 220000 | F13: =D13*E13 -> 7920000 | G13: PIE250770 | H13: 45905
A14: 10 | B14: Vòng bi NTN 6200LLU/2AS | C14: Cái | D14: =SUMIF('[1]Bản đối chiếu chi tiết'!J13:L71,'Chốt - Gộp PO'!B14,'[1]Bản đối chiếu chi tiết'!L13:L71) -> 5 | E14: 108000 | F14: =D14*E14 -> 540000 | G14: PIE250770 | H14: 45905
A15: 11 | B15: Vòng bi NTN 6201LLU/2AS | C15: Cái | D15: =SUMIF('[1]Bản đối chiếu chi tiết'!J14:L72,'Chốt - Gộp PO'!B15,'[1]Bản đối chiếu chi tiết'!L14:L72) -> 5 | E15: 115000 | F15: =D15*E15 -> 575000 | G15: PIE250770 | H15: 45905
A16: 12 | B16: Thiết bị đo nhiệt độ và độ ẩm môi trường, mã HTC-1 | C16: Cái | D16: =SUMIF('[1]Bản đối chiếu chi tiết'!J15:L73,'Chốt - Gộp PO'!B16,'[1]Bản đối chiếu chi tiết'!L15:L73) -> 2 | E16: 965000 | F16: =D16*E16 -> 1930000 | G16: PIE250770 | H16: 45905
A17: 13 | B17: Rơ le SRD-12VDC-SL-C Relay 12V 10A/250V 5 chân CH SONGLE | C17: Chiếc | D17: =SUMIF('[1]Bản đối chiếu chi tiết'!J16:L74,'Chốt - Gộp PO'!B17,'[1]Bản đối chiếu chi tiết'!L16:L74) -> 20 | E17: 12000 | F17: =D17*E17 -> 240000 | G17: PIE250770 | H17: 45905
A18: 14 | B18: Mũi Hàn To 200K | C18: Cái | D18: =SUMIF('[1]Bản đối chiếu chi tiết'!J17:L75,'Chốt - Gộp PO'!B18,'[1]Bản đối chiếu chi tiết'!L17:L75) -> 85 | E18: 19000 | F18: =D18*E18 -> 1615000 | G18: PIE250770 | H18: 45905
A19: 15 | B19: Vít bulông đầu tròn inox M2 x 6 | C19: Cái | D19: =SUMIF('[1]Bản đối chiếu chi tiết'!J18:L76,'Chốt - Gộp PO'!B19,'[1]Bản đối chiếu chi tiết'!L18:L76) -> 200 | E19: 900 | F19: =D19*E19 -> 180000 | G19: PIE250770 | H19: 45905
A20: 16 | B20: Mũi hàn nhỏ 200-SK | C20: Cái | D20: =SUMIF('[1]Bản đối chiếu chi tiết'!J19:L77,'Chốt - Gộp PO'!B20,'[1]Bản đối chiếu chi tiết'!L19:L77) -> 30 | E20: 19000 | F20: =D20*E20 -> 570000 | G20: PIE250770 | H20: 45905
A21: 17 | B21: Đầu xoắn máy đo lực model: HP-50 bằng thép | C21: Cái | D21: =SUMIF('[1]Bản đối chiếu chi tiết'!J20:L78,'Chốt - Gộp PO'!B21,'[1]Bản đối chiếu chi tiết'!L20:L78) -> 1 | E21: 680000 | F21: =D21*E21 -> 680000 | G21: PIE250770 | H21: 45905
F22: =SUBTOTAL(9,F12:F21) -> 16050000
A23: 18 | B23: Thùng đựng linh kiện điện tử ESD bằng nhựa, kt: 310*270*140MM | C23: Cái | D23: =SUMIF('[1]Bản đối chiếu chi tiết'!J21:L79,'Chốt - Gộp PO'!B23,'[1]Bản đối chiếu chi tiết'!L21:L79) -> 10 | E23: 150000 | F23: =D23*E23 -> 1500000 | G23: PIE250678 | H23: 09/09/2025
A24: 19 | B24: Đầu jack M5 đầu nối điện cho dây nguồn DC, điện áp 24V, 5A | C24: Cái | D24: =SUMIF('[1]Bản đối chiếu chi tiết'!J22:L80,'Chốt - Gộp PO'!B24,'[1]Bản đối chiếu chi tiết'!L22:L80) -> 10 | E24: 20000 | F24: =D24*E24 -> 200000 | G24: PIE250678 | H24: 09/09/2025
A25: 20 | B25: DÂY MÁY HÀN QUICK 203H | C25: Cái | D25: =SUMIF('[1]Bản đối chiếu chi tiết'!J23:L81,'Chốt - Gộp PO'!B25,'[1]Bản đối chiếu chi tiết'!L23:L81) -> 5 | E25: 290000 | F25: =D25*E25 -> 1450000 | G25: PIE250678 | H25: 09/09/2025
A26: 21 | B26: Đầu BNC T | C26: Cái | D26: =SUMIF('[1]Bản đối chiếu chi tiết'!J24:L82,'Chốt - Gộp PO'!B26,'[1]Bản đối chiếu chi tiết'!L24:L82) -> 40 | E26: 25000 | F26: =D26*E26 -> 1000000 | G26: PIE250678 | H26: 09/09/2025
A27: 22 | B27: Van bi nhựa, đường kính trong 15mm, dùng để điều chỉnh đóng mở nước | C27: Cái | D27: =SUMIF('[1]Bản đối chiếu chi tiết'!J25:L83,'Chốt - Gộp PO'!B27,'[1]Bản đối chiếu chi tiết'!L25:L83) -> 10 | E27: 84700 | F27: =D27*E27 -> 847000 | G27: PIE250678 | H27: 09/09/2025
A28: 23 | B28: Máy dập gạt tay mini thủ công JS16,kt: 210x120x400mm | C28: Cái | D28: =SUMIF('[1]Bản đối chiếu chi tiết'!J26:L84,'Chốt - Gộp PO'!B28,'[1]Bản đối chiếu chi tiết'!L26:L84) -> 2 | E28: 690000 | F28: =D28*E28 -> 1380000 | G28: PIE250678 | H28: 09/09/2025
A29: 24 | B29: Bộ nguồn, điện áp vào 220VAC,điện áp ra 24VDC, 2A | C29: Cái | D29: =SUMIF('[1]Bản đối chiếu chi tiết'!J27:L85,'Chốt - Gộp PO'!B29,'[1]Bản đối chiếu chi tiết'!L27:L85) -> 2 | E29: 141000 | F29: =D29*E29 -> 282000 | G29: PIE250678 | H29: 09/09/2025
A30: 25 | B30: Cánh quạt máy bắn vít tự động | C30: Cái | D30: =SUMIF('[1]Bản đối chiếu chi tiết'!J28:L86,'Chốt - Gộp PO'!B30,'[1]Bản đối chiếu chi tiết'!L28:L86) -> 10 | E30: 72000 | F30: =D30*E30 -> 720000 | G30: PIE250678 | H30: 09/09/2025
A31: 26 | B31: Ống khí nén nhựa PU 4x2x100m | C31: Cuộn | D31: =SUMIF('[1]Bản đối chiếu chi tiết'!J29:L87,'Chốt - Gộp PO'!B31,'[1]Bản đối chiếu chi tiết'!L29:L87) -> 1 | E31: 350000 | F31: =D31*E31 -> 350000 | G31: PIE250678 | H31: 09/09/2025
A32: 27 | B32: Công tắc gạt on- off MTS-202 | C32: Cái | D32: =SUMIF('[1]Bản đối chiếu chi tiết'!J30:L88,'Chốt - Gộp PO'!B32,'[1]Bản đối chiếu chi tiết'!L30:L88) -> 35 | E32: 39000 | F32: =D32*E32 -> 1365000 | G32: PIE250678 | H32: 09/09/2025
A33: 28 | B33: Dây nguồn 2 chân dài 60cm | C33: Cái | D33: =SUMIF('[1]Bản đối chiếu chi tiết'!J31:L89,'Chốt - Gộp PO'!B33,'[1]Bản đối chiếu chi tiết'!L31:L89) -> 10 | E33: 90000 | F33: =D33*E33 -> 900000 | G33: PIE250678 | H33: 09/09/2025
A34: 29 | B34: Dây curoa SUNDT 1125-3M-15 | C34: Sợi | D34: =SUMIF('[1]Bản đối chiếu chi tiết'!J32:L90,'Chốt - Gộp PO'!B34,'[1]Bản đối chiếu chi tiết'!L32:L90) -> 2 | E34: 235000 | F34: =D34*E34 -> 470000 | G34: PIE250678 | H34: 09/09/2025
... A38: 33 | B38: Giắc cắm kết nối âm thanh XLR Canon Female Soundline NC3FXX, hiệu Soundline | C38: Cái | D38: =SUMIF('[1]Bản đối chiếu chi tiết'!J36:L94,'Chốt - Gộp PO'!B38,'[1]Bản đối chiếu chi tiết'!L36:L94) -> 30 | E38: 50000 | F38: =D38*E38 -> 1500000 | G38: PIE250678 | H38: 09/09/2025
F39: =SUBTOTAL(9,F23:F38) -> 17632000
B40: Tổng tiền | D40: =SUM(D4:D38) -> 1757 | F40: =SUBTOTAL(9,F4:F39) -> 56400000
